[2025-03-14T18:48:22.717+0000] {local_task_job_runner.py:123} INFO - ::group::Pre task execution logs
[2025-03-14T18:48:22.724+0000] {taskinstance.py:2614} INFO - Dependencies all met for dep_context=non-requeueable deps ti=<TaskInstance: test_minio_connection_dag.test_minio_connection manual__2025-03-14T18:48:21.093228+00:00 [queued]>
[2025-03-14T18:48:22.727+0000] {taskinstance.py:2614} INFO - Dependencies all met for dep_context=requeueable deps ti=<TaskInstance: test_minio_connection_dag.test_minio_connection manual__2025-03-14T18:48:21.093228+00:00 [queued]>
[2025-03-14T18:48:22.728+0000] {taskinstance.py:2867} INFO - Starting attempt 1 of 2
[2025-03-14T18:48:22.732+0000] {taskinstance.py:2890} INFO - Executing <Task(PythonOperator): test_minio_connection> on 2025-03-14 18:48:21.093228+00:00
[2025-03-14T18:48:22.736+0000] {warnings.py:112} WARNING - /home/***/.local/lib/python3.12/site-packages/***/task/task_runner/standard_task_runner.py:70: DeprecationWarning: This process (pid=1137) is multi-threaded, use of fork() may lead to deadlocks in the child.
  pid = os.fork()

[2025-03-14T18:48:22.736+0000] {standard_task_runner.py:72} INFO - Started process 1138 to run task
[2025-03-14T18:48:22.737+0000] {standard_task_runner.py:104} INFO - Running: ['***', 'tasks', 'run', 'test_minio_connection_dag', 'test_minio_connection', 'manual__2025-03-14T18:48:21.093228+00:00', '--job-id', '29', '--raw', '--subdir', 'DAGS_FOLDER/sample_dag.py', '--cfg-path', '/tmp/tmpfc0y24c1']
[2025-03-14T18:48:22.738+0000] {standard_task_runner.py:105} INFO - Job 29: Subtask test_minio_connection
[2025-03-14T18:48:22.758+0000] {task_command.py:467} INFO - Running <TaskInstance: test_minio_connection_dag.test_minio_connection manual__2025-03-14T18:48:21.093228+00:00 [running]> on host a389b3fab5c2
[2025-03-14T18:48:22.935+0000] {taskinstance.py:3134} INFO - Exporting env vars: AIRFLOW_CTX_DAG_OWNER='***' AIRFLOW_CTX_DAG_ID='test_minio_connection_dag' AIRFLOW_CTX_TASK_ID='test_minio_connection' AIRFLOW_CTX_EXECUTION_DATE='2025-03-14T18:48:21.093228+00:00' AIRFLOW_CTX_TRY_NUMBER='1' AIRFLOW_CTX_DAG_RUN_ID='manual__2025-03-14T18:48:21.093228+00:00'
[2025-03-14T18:48:22.936+0000] {logging_mixin.py:190} INFO - Task instance is in running state
[2025-03-14T18:48:22.936+0000] {logging_mixin.py:190} INFO -  Previous state of the Task instance: queued
[2025-03-14T18:48:22.936+0000] {logging_mixin.py:190} INFO - Current task name:test_minio_connection state:running start_date:2025-03-14 18:48:22.725132+00:00
[2025-03-14T18:48:22.936+0000] {logging_mixin.py:190} INFO - Dag name:test_minio_connection_dag and current dag run status:running
[2025-03-14T18:48:22.936+0000] {taskinstance.py:732} INFO - ::endgroup::
[2025-03-14T18:48:22.939+0000] {connectionpool.py:868} WARNING - Retrying (Retry(total=4, connect=None, read=None, redirect=None, status=None)) after connection broken by 'NewConnectionError('<urllib3.connection.HTTPConnection object at 0xffff5d419af0>: Failed to establish a new connection: [Errno 111] Connection refused')': /
[2025-03-14T18:48:23.341+0000] {connectionpool.py:868} WARNING - Retrying (Retry(total=3, connect=None, read=None, redirect=None, status=None)) after connection broken by 'NewConnectionError('<urllib3.connection.HTTPConnection object at 0xffff5d9d7da0>: Failed to establish a new connection: [Errno 111] Connection refused')': /
[2025-03-14T18:48:24.144+0000] {connectionpool.py:868} WARNING - Retrying (Retry(total=2, connect=None, read=None, redirect=None, status=None)) after connection broken by 'NewConnectionError('<urllib3.connection.HTTPConnection object at 0xffff5d48cec0>: Failed to establish a new connection: [Errno 111] Connection refused')': /
[2025-03-14T18:48:25.749+0000] {connectionpool.py:868} WARNING - Retrying (Retry(total=1, connect=None, read=None, redirect=None, status=None)) after connection broken by 'NewConnectionError('<urllib3.connection.HTTPConnection object at 0xffff5d48cb30>: Failed to establish a new connection: [Errno 111] Connection refused')': /
[2025-03-14T18:48:28.955+0000] {connectionpool.py:868} WARNING - Retrying (Retry(total=0, connect=None, read=None, redirect=None, status=None)) after connection broken by 'NewConnectionError('<urllib3.connection.HTTPConnection object at 0xffff5d48cd40>: Failed to establish a new connection: [Errno 111] Connection refused')': /
[2025-03-14T18:48:28.957+0000] {logging_mixin.py:190} INFO - An unexpected error occurred: HTTPConnectionPool(host='localhost', port=9000): Max retries exceeded with url: / (Caused by NewConnectionError('<urllib3.connection.HTTPConnection object at 0xffff5d48d4c0>: Failed to establish a new connection: [Errno 111] Connection refused'))
[2025-03-14T18:48:28.959+0000] {python.py:240} INFO - Done. Returned value was: None
[2025-03-14T18:48:28.968+0000] {taskinstance.py:341} INFO - ::group::Post task execution logs
[2025-03-14T18:48:28.968+0000] {taskinstance.py:353} INFO - Marking task as SUCCESS. dag_id=test_minio_connection_dag, task_id=test_minio_connection, run_id=manual__2025-03-14T18:48:21.093228+00:00, execution_date=20250314T184821, start_date=20250314T184822, end_date=20250314T184828
[2025-03-14T18:48:28.987+0000] {logging_mixin.py:190} INFO - Task instance in success state
[2025-03-14T18:48:28.987+0000] {logging_mixin.py:190} INFO -  Previous state of the Task instance: running
[2025-03-14T18:48:28.987+0000] {logging_mixin.py:190} INFO - Dag name:test_minio_connection_dag queued_at:2025-03-14 18:48:21.103304+00:00
[2025-03-14T18:48:28.988+0000] {logging_mixin.py:190} INFO - Task hostname:a389b3fab5c2 operator:PythonOperator
[2025-03-14T18:48:29.022+0000] {local_task_job_runner.py:266} INFO - Task exited with return code 0
[2025-03-14T18:48:29.032+0000] {taskinstance.py:3901} INFO - 0 downstream tasks scheduled from follow-on schedule check
[2025-03-14T18:48:29.033+0000] {local_task_job_runner.py:245} INFO - ::endgroup::
