[2025-03-14T18:05:17.685+0000] {local_task_job_runner.py:123} INFO - ::group::Pre task execution logs
[2025-03-14T18:05:17.694+0000] {taskinstance.py:2614} INFO - Dependencies all met for dep_context=non-requeueable deps ti=<TaskInstance: list_minio_files_dag.list_files_in_bucket manual__2025-03-14T18:05:12+00:00 [queued]>
[2025-03-14T18:05:17.697+0000] {taskinstance.py:2614} INFO - Dependencies all met for dep_context=requeueable deps ti=<TaskInstance: list_minio_files_dag.list_files_in_bucket manual__2025-03-14T18:05:12+00:00 [queued]>
[2025-03-14T18:05:17.697+0000] {taskinstance.py:2867} INFO - Starting attempt 1 of 2
[2025-03-14T18:05:17.702+0000] {taskinstance.py:2890} INFO - Executing <Task(PythonOperator): list_files_in_bucket> on 2025-03-14 18:05:12+00:00
[2025-03-14T18:05:17.705+0000] {warnings.py:112} WARNING - /home/***/.local/lib/python3.12/site-packages/***/task/task_runner/standard_task_runner.py:70: DeprecationWarning: This process (pid=522) is multi-threaded, use of fork() may lead to deadlocks in the child.
  pid = os.fork()

[2025-03-14T18:05:17.706+0000] {standard_task_runner.py:72} INFO - Started process 523 to run task
[2025-03-14T18:05:17.707+0000] {standard_task_runner.py:104} INFO - Running: ['***', 'tasks', 'run', 'list_minio_files_dag', 'list_files_in_bucket', 'manual__2025-03-14T18:05:12+00:00', '--job-id', '13', '--raw', '--subdir', 'DAGS_FOLDER/sample_dag.py', '--cfg-path', '/tmp/tmpttifw4w4']
[2025-03-14T18:05:17.707+0000] {standard_task_runner.py:105} INFO - Job 13: Subtask list_files_in_bucket
[2025-03-14T18:05:17.733+0000] {task_command.py:467} INFO - Running <TaskInstance: list_minio_files_dag.list_files_in_bucket manual__2025-03-14T18:05:12+00:00 [running]> on host a389b3fab5c2
[2025-03-14T18:05:17.901+0000] {taskinstance.py:3134} INFO - Exporting env vars: AIRFLOW_CTX_DAG_OWNER='***' AIRFLOW_CTX_DAG_ID='list_minio_files_dag' AIRFLOW_CTX_TASK_ID='list_files_in_bucket' AIRFLOW_CTX_EXECUTION_DATE='2025-03-14T18:05:12+00:00' AIRFLOW_CTX_TRY_NUMBER='1' AIRFLOW_CTX_DAG_RUN_ID='manual__2025-03-14T18:05:12+00:00'
[2025-03-14T18:05:17.902+0000] {logging_mixin.py:190} INFO - Task instance is in running state
[2025-03-14T18:05:17.902+0000] {logging_mixin.py:190} INFO -  Previous state of the Task instance: queued
[2025-03-14T18:05:17.902+0000] {logging_mixin.py:190} INFO - Current task name:list_files_in_bucket state:running start_date:2025-03-14 18:05:17.694389+00:00
[2025-03-14T18:05:17.902+0000] {logging_mixin.py:190} INFO - Dag name:list_minio_files_dag and current dag run status:running
[2025-03-14T18:05:17.902+0000] {taskinstance.py:732} INFO - ::endgroup::
[2025-03-14T18:05:17.903+0000] {logging_mixin.py:190} INFO - Files in bucket 'document':
[2025-03-14T18:05:17.904+0000] {connectionpool.py:868} WARNING - Retrying (Retry(total=4, connect=None, read=None, redirect=None, status=None)) after connection broken by 'NewConnectionError('<urllib3.connection.HTTPConnection object at 0xffff5d4797c0>: Failed to establish a new connection: [Errno 111] Connection refused')': /document?location=
[2025-03-14T18:05:18.305+0000] {connectionpool.py:868} WARNING - Retrying (Retry(total=3, connect=None, read=None, redirect=None, status=None)) after connection broken by 'NewConnectionError('<urllib3.connection.HTTPConnection object at 0xffff5d479fa0>: Failed to establish a new connection: [Errno 111] Connection refused')': /document?location=
[2025-03-14T18:05:19.106+0000] {connectionpool.py:868} WARNING - Retrying (Retry(total=2, connect=None, read=None, redirect=None, status=None)) after connection broken by 'NewConnectionError('<urllib3.connection.HTTPConnection object at 0xffff5d47a1b0>: Failed to establish a new connection: [Errno 111] Connection refused')': /document?location=
[2025-03-14T18:05:20.708+0000] {connectionpool.py:868} WARNING - Retrying (Retry(total=1, connect=None, read=None, redirect=None, status=None)) after connection broken by 'NewConnectionError('<urllib3.connection.HTTPConnection object at 0xffff5d479f40>: Failed to establish a new connection: [Errno 111] Connection refused')': /document?location=
[2025-03-14T18:05:23.913+0000] {connectionpool.py:868} WARNING - Retrying (Retry(total=0, connect=None, read=None, redirect=None, status=None)) after connection broken by 'NewConnectionError('<urllib3.connection.HTTPConnection object at 0xffff5d47a270>: Failed to establish a new connection: [Errno 111] Connection refused')': /document?location=
[2025-03-14T18:05:23.915+0000] {taskinstance.py:3313} ERROR - Task failed with exception
Traceback (most recent call last):
  File "/home/airflow/.local/lib/python3.12/site-packages/urllib3/connection.py", line 198, in _new_conn
    sock = connection.create_connection(
           ^^^^^^^^^^^^^^^^^^^^^^^^^^^^^
  File "/home/airflow/.local/lib/python3.12/site-packages/urllib3/util/connection.py", line 85, in create_connection
    raise err
  File "/home/airflow/.local/lib/python3.12/site-packages/urllib3/util/connection.py", line 73, in create_connection
    sock.connect(sa)
ConnectionRefusedError: [Errno 111] Connection refused

The above exception was the direct cause of the following exception:

Traceback (most recent call last):
  File "/home/airflow/.local/lib/python3.12/site-packages/urllib3/connectionpool.py", line 787, in urlopen
    response = self._make_request(
               ^^^^^^^^^^^^^^^^^^^
  File "/home/airflow/.local/lib/python3.12/site-packages/urllib3/connectionpool.py", line 493, in _make_request
    conn.request(
  File "/home/airflow/.local/lib/python3.12/site-packages/urllib3/connection.py", line 445, in request
    self.endheaders()
  File "/usr/local/lib/python3.12/http/client.py", line 1333, in endheaders
    self._send_output(message_body, encode_chunked=encode_chunked)
  File "/usr/local/lib/python3.12/http/client.py", line 1093, in _send_output
    self.send(msg)
  File "/usr/local/lib/python3.12/http/client.py", line 1037, in send
    self.connect()
  File "/home/airflow/.local/lib/python3.12/site-packages/urllib3/connection.py", line 276, in connect
    self.sock = self._new_conn()
                ^^^^^^^^^^^^^^^^
  File "/home/airflow/.local/lib/python3.12/site-packages/urllib3/connection.py", line 213, in _new_conn
    raise NewConnectionError(
urllib3.exceptions.NewConnectionError: <urllib3.connection.HTTPConnection object at 0xffff5d47a600>: Failed to establish a new connection: [Errno 111] Connection refused

The above exception was the direct cause of the following exception:

Traceback (most recent call last):
  File "/home/airflow/.local/lib/python3.12/site-packages/airflow/models/taskinstance.py", line 768, in _execute_task
    result = _execute_callable(context=context, **execute_callable_kwargs)
             ^^^^^^^^^^^^^^^^^^^^^^^^^^^^^^^^^^^^^^^^^^^^^^^^^^^^^^^^^^^^^
  File "/home/airflow/.local/lib/python3.12/site-packages/airflow/models/taskinstance.py", line 734, in _execute_callable
    return ExecutionCallableRunner(
           ^^^^^^^^^^^^^^^^^^^^^^^^
  File "/home/airflow/.local/lib/python3.12/site-packages/airflow/utils/operator_helpers.py", line 252, in run
    return self.func(*args, **kwargs)
           ^^^^^^^^^^^^^^^^^^^^^^^^^^
  File "/home/airflow/.local/lib/python3.12/site-packages/airflow/models/baseoperator.py", line 424, in wrapper
    return func(self, *args, **kwargs)
           ^^^^^^^^^^^^^^^^^^^^^^^^^^^
  File "/home/airflow/.local/lib/python3.12/site-packages/airflow/operators/python.py", line 238, in execute
    return_value = self.execute_callable()
                   ^^^^^^^^^^^^^^^^^^^^^^^
  File "/home/airflow/.local/lib/python3.12/site-packages/airflow/operators/python.py", line 256, in execute_callable
    return runner.run(*self.op_args, **self.op_kwargs)
           ^^^^^^^^^^^^^^^^^^^^^^^^^^^^^^^^^^^^^^^^^^^
  File "/home/airflow/.local/lib/python3.12/site-packages/airflow/utils/operator_helpers.py", line 252, in run
    return self.func(*args, **kwargs)
           ^^^^^^^^^^^^^^^^^^^^^^^^^^
  File "/opt/airflow/dags/sample_dag.py", line 27, in list_files_in_bucket
    for file in files:
                ^^^^^
  File "/home/airflow/.local/lib/python3.12/site-packages/minio/api.py", line 3191, in _list_objects
    response = self._execute(
               ^^^^^^^^^^^^^^
  File "/home/airflow/.local/lib/python3.12/site-packages/minio/api.py", line 438, in _execute
    region = self._get_region(bucket_name)
             ^^^^^^^^^^^^^^^^^^^^^^^^^^^^^
  File "/home/airflow/.local/lib/python3.12/site-packages/minio/api.py", line 495, in _get_region
    response = self._url_open(
               ^^^^^^^^^^^^^^^
  File "/home/airflow/.local/lib/python3.12/site-packages/minio/api.py", line 303, in _url_open
    response = self._http.urlopen(
               ^^^^^^^^^^^^^^^^^^^
  File "/home/airflow/.local/lib/python3.12/site-packages/urllib3/poolmanager.py", line 443, in urlopen
    response = conn.urlopen(method, u.request_uri, **kw)
               ^^^^^^^^^^^^^^^^^^^^^^^^^^^^^^^^^^^^^^^^^
  File "/home/airflow/.local/lib/python3.12/site-packages/urllib3/connectionpool.py", line 871, in urlopen
    return self.urlopen(
           ^^^^^^^^^^^^^
  File "/home/airflow/.local/lib/python3.12/site-packages/urllib3/connectionpool.py", line 871, in urlopen
    return self.urlopen(
           ^^^^^^^^^^^^^
  File "/home/airflow/.local/lib/python3.12/site-packages/urllib3/connectionpool.py", line 871, in urlopen
    return self.urlopen(
           ^^^^^^^^^^^^^
  [Previous line repeated 2 more times]
  File "/home/airflow/.local/lib/python3.12/site-packages/urllib3/connectionpool.py", line 841, in urlopen
    retries = retries.increment(
              ^^^^^^^^^^^^^^^^^^
  File "/home/airflow/.local/lib/python3.12/site-packages/urllib3/util/retry.py", line 519, in increment
    raise MaxRetryError(_pool, url, reason) from reason  # type: ignore[arg-type]
    ^^^^^^^^^^^^^^^^^^^^^^^^^^^^^^^^^^^^^^^^^^^^^^^^^^^
urllib3.exceptions.MaxRetryError: HTTPConnectionPool(host='localhost', port=9000): Max retries exceeded with url: /document?location= (Caused by NewConnectionError('<urllib3.connection.HTTPConnection object at 0xffff5d47a600>: Failed to establish a new connection: [Errno 111] Connection refused'))
[2025-03-14T18:05:23.936+0000] {logging_mixin.py:190} INFO - Task instance in failure state
[2025-03-14T18:05:23.937+0000] {logging_mixin.py:190} INFO - Task start:2025-03-14 18:05:17.694389+00:00 end:2025-03-14 18:05:23.936159+00:00 duration:6.24177
[2025-03-14T18:05:23.937+0000] {logging_mixin.py:190} INFO - Task:<Task(PythonOperator): list_files_in_bucket> dag:<DAG: list_minio_files_dag> dagrun:<DagRun list_minio_files_dag @ 2025-03-14 18:05:12+00:00: manual__2025-03-14T18:05:12+00:00, state:running, queued_at: 2025-03-14 18:05:16.545348+00:00. externally triggered: True>
[2025-03-14T18:05:23.937+0000] {logging_mixin.py:190} INFO - Failure caused by HTTPConnectionPool(host='localhost', port=9000): Max retries exceeded with url: /document?location= (Caused by NewConnectionError('<urllib3.connection.HTTPConnection object at 0xffff5d47a600>: Failed to establish a new connection: [Errno 111] Connection refused'))
[2025-03-14T18:05:23.937+0000] {taskinstance.py:1226} INFO - Marking task as UP_FOR_RETRY. dag_id=list_minio_files_dag, task_id=list_files_in_bucket, run_id=manual__2025-03-14T18:05:12+00:00, execution_date=20250314T180512, start_date=20250314T180517, end_date=20250314T180523
[2025-03-14T18:05:23.963+0000] {taskinstance.py:341} INFO - ::group::Post task execution logs
[2025-03-14T18:05:23.963+0000] {standard_task_runner.py:124} ERROR - Failed to execute job 13 for task list_files_in_bucket (HTTPConnectionPool(host='localhost', port=9000): Max retries exceeded with url: /document?location= (Caused by NewConnectionError('<urllib3.connection.HTTPConnection object at 0xffff5d47a600>: Failed to establish a new connection: [Errno 111] Connection refused')); 523)
Traceback (most recent call last):
  File "/home/airflow/.local/lib/python3.12/site-packages/urllib3/connection.py", line 198, in _new_conn
    sock = connection.create_connection(
           ^^^^^^^^^^^^^^^^^^^^^^^^^^^^^
  File "/home/airflow/.local/lib/python3.12/site-packages/urllib3/util/connection.py", line 85, in create_connection
    raise err
  File "/home/airflow/.local/lib/python3.12/site-packages/urllib3/util/connection.py", line 73, in create_connection
    sock.connect(sa)
ConnectionRefusedError: [Errno 111] Connection refused

The above exception was the direct cause of the following exception:

Traceback (most recent call last):
  File "/home/airflow/.local/lib/python3.12/site-packages/urllib3/connectionpool.py", line 787, in urlopen
    response = self._make_request(
               ^^^^^^^^^^^^^^^^^^^
  File "/home/airflow/.local/lib/python3.12/site-packages/urllib3/connectionpool.py", line 493, in _make_request
    conn.request(
  File "/home/airflow/.local/lib/python3.12/site-packages/urllib3/connection.py", line 445, in request
    self.endheaders()
  File "/usr/local/lib/python3.12/http/client.py", line 1333, in endheaders
    self._send_output(message_body, encode_chunked=encode_chunked)
  File "/usr/local/lib/python3.12/http/client.py", line 1093, in _send_output
    self.send(msg)
  File "/usr/local/lib/python3.12/http/client.py", line 1037, in send
    self.connect()
  File "/home/airflow/.local/lib/python3.12/site-packages/urllib3/connection.py", line 276, in connect
    self.sock = self._new_conn()
                ^^^^^^^^^^^^^^^^
  File "/home/airflow/.local/lib/python3.12/site-packages/urllib3/connection.py", line 213, in _new_conn
    raise NewConnectionError(
urllib3.exceptions.NewConnectionError: <urllib3.connection.HTTPConnection object at 0xffff5d47a600>: Failed to establish a new connection: [Errno 111] Connection refused

The above exception was the direct cause of the following exception:

Traceback (most recent call last):
  File "/home/airflow/.local/lib/python3.12/site-packages/airflow/task/task_runner/standard_task_runner.py", line 117, in _start_by_fork
    ret = args.func(args, dag=self.dag)
          ^^^^^^^^^^^^^^^^^^^^^^^^^^^^^
  File "/home/airflow/.local/lib/python3.12/site-packages/airflow/cli/cli_config.py", line 49, in command
    return func(*args, **kwargs)
           ^^^^^^^^^^^^^^^^^^^^^
  File "/home/airflow/.local/lib/python3.12/site-packages/airflow/utils/cli.py", line 116, in wrapper
    return f(*args, **kwargs)
           ^^^^^^^^^^^^^^^^^^
  File "/home/airflow/.local/lib/python3.12/site-packages/airflow/cli/commands/task_command.py", line 483, in task_run
    task_return_code = _run_task_by_selected_method(args, _dag, ti)
                       ^^^^^^^^^^^^^^^^^^^^^^^^^^^^^^^^^^^^^^^^^^^^
  File "/home/airflow/.local/lib/python3.12/site-packages/airflow/cli/commands/task_command.py", line 256, in _run_task_by_selected_method
    return _run_raw_task(args, ti)
           ^^^^^^^^^^^^^^^^^^^^^^^
  File "/home/airflow/.local/lib/python3.12/site-packages/airflow/cli/commands/task_command.py", line 341, in _run_raw_task
    return ti._run_raw_task(
           ^^^^^^^^^^^^^^^^^
  File "/home/airflow/.local/lib/python3.12/site-packages/airflow/utils/session.py", line 97, in wrapper
    return func(*args, session=session, **kwargs)
           ^^^^^^^^^^^^^^^^^^^^^^^^^^^^^^^^^^^^^^
  File "/home/airflow/.local/lib/python3.12/site-packages/airflow/models/taskinstance.py", line 3006, in _run_raw_task
    return _run_raw_task(
           ^^^^^^^^^^^^^^
  File "/home/airflow/.local/lib/python3.12/site-packages/airflow/models/taskinstance.py", line 274, in _run_raw_task
    TaskInstance._execute_task_with_callbacks(
  File "/home/airflow/.local/lib/python3.12/site-packages/airflow/models/taskinstance.py", line 3161, in _execute_task_with_callbacks
    result = self._execute_task(context, task_orig)
             ^^^^^^^^^^^^^^^^^^^^^^^^^^^^^^^^^^^^^^
  File "/home/airflow/.local/lib/python3.12/site-packages/airflow/models/taskinstance.py", line 3185, in _execute_task
    return _execute_task(self, context, task_orig)
           ^^^^^^^^^^^^^^^^^^^^^^^^^^^^^^^^^^^^^^^
  File "/home/airflow/.local/lib/python3.12/site-packages/airflow/models/taskinstance.py", line 768, in _execute_task
    result = _execute_callable(context=context, **execute_callable_kwargs)
             ^^^^^^^^^^^^^^^^^^^^^^^^^^^^^^^^^^^^^^^^^^^^^^^^^^^^^^^^^^^^^
  File "/home/airflow/.local/lib/python3.12/site-packages/airflow/models/taskinstance.py", line 734, in _execute_callable
    return ExecutionCallableRunner(
           ^^^^^^^^^^^^^^^^^^^^^^^^
  File "/home/airflow/.local/lib/python3.12/site-packages/airflow/utils/operator_helpers.py", line 252, in run
    return self.func(*args, **kwargs)
           ^^^^^^^^^^^^^^^^^^^^^^^^^^
  File "/home/airflow/.local/lib/python3.12/site-packages/airflow/models/baseoperator.py", line 424, in wrapper
    return func(self, *args, **kwargs)
           ^^^^^^^^^^^^^^^^^^^^^^^^^^^
  File "/home/airflow/.local/lib/python3.12/site-packages/airflow/operators/python.py", line 238, in execute
    return_value = self.execute_callable()
                   ^^^^^^^^^^^^^^^^^^^^^^^
  File "/home/airflow/.local/lib/python3.12/site-packages/airflow/operators/python.py", line 256, in execute_callable
    return runner.run(*self.op_args, **self.op_kwargs)
           ^^^^^^^^^^^^^^^^^^^^^^^^^^^^^^^^^^^^^^^^^^^
  File "/home/airflow/.local/lib/python3.12/site-packages/airflow/utils/operator_helpers.py", line 252, in run
    return self.func(*args, **kwargs)
           ^^^^^^^^^^^^^^^^^^^^^^^^^^
  File "/opt/airflow/dags/sample_dag.py", line 27, in list_files_in_bucket
    for file in files:
                ^^^^^
  File "/home/airflow/.local/lib/python3.12/site-packages/minio/api.py", line 3191, in _list_objects
    response = self._execute(
               ^^^^^^^^^^^^^^
  File "/home/airflow/.local/lib/python3.12/site-packages/minio/api.py", line 438, in _execute
    region = self._get_region(bucket_name)
             ^^^^^^^^^^^^^^^^^^^^^^^^^^^^^
  File "/home/airflow/.local/lib/python3.12/site-packages/minio/api.py", line 495, in _get_region
    response = self._url_open(
               ^^^^^^^^^^^^^^^
  File "/home/airflow/.local/lib/python3.12/site-packages/minio/api.py", line 303, in _url_open
    response = self._http.urlopen(
               ^^^^^^^^^^^^^^^^^^^
  File "/home/airflow/.local/lib/python3.12/site-packages/urllib3/poolmanager.py", line 443, in urlopen
    response = conn.urlopen(method, u.request_uri, **kw)
               ^^^^^^^^^^^^^^^^^^^^^^^^^^^^^^^^^^^^^^^^^
  File "/home/airflow/.local/lib/python3.12/site-packages/urllib3/connectionpool.py", line 871, in urlopen
    return self.urlopen(
           ^^^^^^^^^^^^^
  File "/home/airflow/.local/lib/python3.12/site-packages/urllib3/connectionpool.py", line 871, in urlopen
    return self.urlopen(
           ^^^^^^^^^^^^^
  File "/home/airflow/.local/lib/python3.12/site-packages/urllib3/connectionpool.py", line 871, in urlopen
    return self.urlopen(
           ^^^^^^^^^^^^^
  [Previous line repeated 2 more times]
  File "/home/airflow/.local/lib/python3.12/site-packages/urllib3/connectionpool.py", line 841, in urlopen
    retries = retries.increment(
              ^^^^^^^^^^^^^^^^^^
  File "/home/airflow/.local/lib/python3.12/site-packages/urllib3/util/retry.py", line 519, in increment
    raise MaxRetryError(_pool, url, reason) from reason  # type: ignore[arg-type]
    ^^^^^^^^^^^^^^^^^^^^^^^^^^^^^^^^^^^^^^^^^^^^^^^^^^^
urllib3.exceptions.MaxRetryError: HTTPConnectionPool(host='localhost', port=9000): Max retries exceeded with url: /document?location= (Caused by NewConnectionError('<urllib3.connection.HTTPConnection object at 0xffff5d47a600>: Failed to establish a new connection: [Errno 111] Connection refused'))
[2025-03-14T18:05:24.013+0000] {local_task_job_runner.py:266} INFO - Task exited with return code 1
[2025-03-14T18:05:24.027+0000] {taskinstance.py:3901} INFO - 0 downstream tasks scheduled from follow-on schedule check
[2025-03-14T18:05:24.028+0000] {local_task_job_runner.py:245} INFO - ::endgroup::
